<?xml version="1.0" encoding="utf-8"?>
<testsuites>
    <testsuite name="pytest" errors="0" failures="1" skipped="0" tests="4"
        timestamp="2023-11-06T11:17:04.011072" hostname="VFHNWJDWH9.local">
        <testcase classname="api.temp.calculator.test_calculator" name="test_add" />
        <testcase classname="api.temp.calculator.test_calculator" name="test_subtract" />
        <testcase classname="api.temp.calculator.test_calculator" name="test_multiply" />
        <testcase classname="api.temp.calculator.test_calculator" name="test_divide">
            <failure
                message="assert 1.0 == 0.5&#10; +  where 1.0 = &lt;function Calculator.divide at 0x104c9eb90&gt;(1, 2)&#10; +    where &lt;function Calculator.divide at 0x104c9eb90&gt; = Calculator.divide">def
                test_divide():\n&gt; assert Calculator.divide(1, 2) == 0.5\nE assert 1.0 == 0.5\nE +
                where 1.0 = &lt;function Calculator.divide at 0x104c9eb90&gt;(1, 2)\nE + where
                &lt;function Calculator.divide at 0x104c9eb90&gt; =
                Calculator.divide\n\napi/temp/calculator/test_calculator.py:30: AssertionError</failure>
        </testcase>
    </testsuite>
</testsuites>